Traceback (most recent call last):
  File "/usr/local/lib/python3.12/dist-packages/jupyter_core/utils/__init__.py", line 154, in wrapped
    asyncio.get_running_loop()
RuntimeError: no running event loop

During handling of the above exception, another exception occurred:

Traceback (most recent call last):
  File "/usr/local/lib/python3.12/dist-packages/jupyter_cache/executors/utils.py", line 58, in single_nb_execution
    executenb(
  File "/usr/local/lib/python3.12/dist-packages/nbclient/client.py", line 1319, in execute
    return NotebookClient(nb=nb, resources=resources, km=km, **kwargs).execute()
           ^^^^^^^^^^^^^^^^^^^^^^^^^^^^^^^^^^^^^^^^^^^^^^^^^^^^^^^^^^^^^^^^^^^^^
  File "/usr/local/lib/python3.12/dist-packages/jupyter_core/utils/__init__.py", line 158, in wrapped
    return loop.run_until_complete(inner)
           ^^^^^^^^^^^^^^^^^^^^^^^^^^^^^^
  File "/usr/lib/python3.12/asyncio/base_events.py", line 691, in run_until_complete
    return future.result()
           ^^^^^^^^^^^^^^^
  File "/usr/local/lib/python3.12/dist-packages/nbclient/client.py", line 709, in async_execute
    await self.async_execute_cell(
  File "/usr/local/lib/python3.12/dist-packages/nbclient/client.py", line 1062, in async_execute_cell
    await self._check_raise_for_error(cell, cell_index, exec_reply)
  File "/usr/local/lib/python3.12/dist-packages/nbclient/client.py", line 918, in _check_raise_for_error
    raise CellExecutionError.from_cell_and_msg(cell, exec_reply_content)
nbclient.exceptions.CellExecutionError: An error occurred while executing the following cell:
------------------
import pymysql
import pandas as pd
from tabulate import tabulate

# Konfigurasi koneksi ke database Aiven MySQL
host = "mysql23-112-irismysql23-112.h.aivencloud.com"
port = 15786
user = "avnadmin"
password = "AVNS_cTNd4CUt1kk0Z7MPIC1"
database = "defaultdb"

# Buat koneksi
mysql_conn = pymysql.connect(
    host=host,
    port=port,
    user=user,
    password=password,
    database=database,
    ssl={'ssl': {}}  # Jika menggunakan SSL
)


def fetch_mysql_data():
    try:
        conn = pymysql.connect(**mysql_config)
        cursor = conn.cursor()
        query = 'SELECT * FROM ecolipsd.ecoli_data;'
        cursor.execute(query)
        data = cursor.fetchall()
        columns = [desc[0] for desc in cursor.description]
        cursor.close()
        conn.close()
        df = pd.DataFrame(data, columns=columns)

        return df
    except pymysql.err.OperationalError as e:
        print(f"Error connecting to MySQL: {e}")
        return pd.DataFrame()


df = fetch_mysql_data()
print(tabulate(df, headers='keys', tablefmt='grid'))
------------------


[0;31m---------------------------------------------------------------------------[0m
[0;31mNameError[0m                                 Traceback (most recent call last)
[0;32m/tmp/ipython-input-3066875912.py[0m in [0;36m<cell line: 0>[0;34m()[0m
[1;32m     39[0m [0;34m[0m[0m
[1;32m     40[0m [0;34m[0m[0m
[0;32m---> 41[0;31m [0mdf[0m [0;34m=[0m [0mfetch_mysql_data[0m[0;34m([0m[0;34m)[0m[0;34m[0m[0;34m[0m[0m
[0m[1;32m     42[0m [0mprint[0m[0;34m([0m[0mtabulate[0m[0;34m([0m[0mdf[0m[0;34m,[0m [0mheaders[0m[0;34m=[0m[0;34m'keys'[0m[0;34m,[0m [0mtablefmt[0m[0;34m=[0m[0;34m'grid'[0m[0;34m)[0m[0;34m)[0m[0;34m[0m[0;34m[0m[0m

[0;32m/tmp/ipython-input-3066875912.py[0m in [0;36mfetch_mysql_data[0;34m()[0m
[1;32m     23[0m [0;32mdef[0m [0mfetch_mysql_data[0m[0;34m([0m[0;34m)[0m[0;34m:[0m[0;34m[0m[0;34m[0m[0m
[1;32m     24[0m     [0;32mtry[0m[0;34m:[0m[0;34m[0m[0;34m[0m[0m
[0;32m---> 25[0;31m         [0mconn[0m [0;34m=[0m [0mpymysql[0m[0;34m.[0m[0mconnect[0m[0;34m([0m[0;34m**[0m[0mmysql_config[0m[0;34m)[0m[0;34m[0m[0;34m[0m[0m
[0m[1;32m     26[0m         [0mcursor[0m [0;34m=[0m [0mconn[0m[0;34m.[0m[0mcursor[0m[0;34m([0m[0;34m)[0m[0;34m[0m[0;34m[0m[0m
[1;32m     27[0m         [0mquery[0m [0;34m=[0m [0;34m'SELECT * FROM ecolipsd.ecoli_data;'[0m[0;34m[0m[0;34m[0m[0m

[0;31mNameError[0m: name 'mysql_config' is not defined

